<?xml version="1.0" ?>
<!--
  This is not a standalone urdf for kobuki. It simply defines the 'kobuki' tag that can
  be incorporated by other urdf files (e.g. turtlebot).

  See kobuki_standalone.urdf.xacro for a standalone urdf to be tested with
      kobuki_description/launch/view_model.launch
 -->
<robot name="kobuki" xmlns:xacro="http://ros.org/wiki/xacro">
  <xacro:include filename="$(find jaime_description)/urdf/common_properties.urdf.xacro"/>
  <xacro:include filename="$(find jaime_description)/urdf/jaime_sensors_properties.urdf.xacro"/>
  <xacro:include filename="$(find jaime_description)/urdf/jaime_gazebo.urdf.xacro"/>

  <material name="black">
    <color rgba="0 0 0 1"/>
  </material>

  <material name="white">
    <color rgba="1 1 1 1"/>
  </material>

  <material name="blue">
    <color rgba="0 0 0.8 1"/>
  </material>

  <!-- Kobuki -->
  <xacro:macro name="kobuki">
    <link name="base_footprint"/>
    <!--
       Base link is set at the bottom of the base mould.
       This is done to be compatible with the way base link
       was configured for turtlebot 1. Refer to

       https://github.com/turtlebot/turtlebot/issues/40

       To put the base link at the more oft used wheel
       axis, set the z-distance from the base_footprint
       to 0.352.
      -->
    <joint name="base_joint" type="fixed">
      <origin xyz="0 0 0.0102" rpy="0 0 0" />
      <parent link="base_footprint"/>
      <child link="base_link" />
    </joint>
    <link name="base_link">
      <visual>
        <geometry>
          <!-- new mesh -->
          <mesh filename="package://jaime_description/meshes/main_body.dae" />
        </geometry>
        <origin xyz="0.001 0 0.05199" rpy="0 0 0"/>
      </visual>
      <collision name="base">
        <geometry>
          <cylinder length="0.10938" radius="0.178"/>
        </geometry>
        <origin xyz="0.0 0 0.05949" rpy="0 0 0"/>
      </collision>
      <inertial>
        <!-- COM experimentally determined -->
        <origin xyz="0.01 0 0"/>
        <mass value="2.4"/> <!-- 2.4/2.6 kg for small/big battery pack -->
        <!-- Kobuki's inertia tensor is approximated by a cylinder with homogeneous mass distribution
             More details: http://en.wikipedia.org/wiki/List_of_moment_of_inertia_tensors
             m = 2.4 kg; h = 0.09 m; r = 0.175 m
             ixx = 1/12 * m * (3 * r^2 + h^2)
             iyy = 1/12 * m * (3 * r^2 + h^2)
             izz = 1/2 * m * r^2
          -->
        <inertia ixx="0.019995" ixy="0.0" ixz="0.0"
                 iyy="0.019995" iyz="0.0"
                 izz="0.03675" />
      </inertial>
    </link>

    <joint name="wheel_left_joint" type="continuous">
      <parent link="base_link"/>
      <child link="wheel_left_link"/>
      <origin xyz="0.00 ${0.23/2} 0.0250" rpy="${-M_PI/2} 0 0"/>
      <axis xyz="0 0 1"/>
    </joint>
    <link name="wheel_left_link">
      <visual>
        <geometry>
          <mesh filename="package://jaime_description/meshes/wheel.dae"/>
        </geometry>
        <origin xyz="0 0 0" rpy="0 0 0"/>
      </visual>
      <collision>
        <geometry>
          <cylinder length="0.0206" radius="0.0352"/>
        </geometry>
        <origin rpy="0 0 0" xyz="0 0 0"/>
      </collision>
      <inertial>
        <mass value="0.01" />
        <origin xyz="0 0 0" />
        <inertia ixx="0.001" ixy="0.0" ixz="0.0"
                 iyy="0.001" iyz="0.0"
                 izz="0.001" />
      </inertial>
    </link>

    <joint name="wheel_right_joint" type="continuous">
      <parent link="base_link"/>
      <child link="wheel_right_link"/>
      <origin xyz="0.00 -${0.23/2} 0.0250" rpy="${-M_PI/2} 0 0"/>
      <axis xyz="0 0 1"/>
    </joint>
    <link name="wheel_right_link">
      <visual>
        <geometry>
          <mesh filename="package://jaime_description/meshes/wheel.dae"/>
        </geometry>
        <origin xyz="0 0 0" rpy="0 0 0"/>
      </visual>
      <collision>
        <geometry>
          <cylinder length="0.0206" radius="0.0350"/>
        </geometry>
        <origin rpy="0 0 0" xyz="0 0 0"/>
      </collision>
      <inertial>
        <mass value="0.01" />
        <origin xyz="0 0 0" />
        <inertia ixx="0.001" ixy="0.0" ixz="0.0"
                 iyy="0.001" iyz="0.0"
                 izz="0.001" />
      </inertial>
    </link>

    <joint name="caster_front_joint" type="fixed">
      <parent link="base_link"/>
      <child link="caster_front_link"/>
      <origin xyz="0.115 0.0 0.007" rpy="${-M_PI/2} 0 0"/>
    </joint>
    <link name="caster_front_link">
      <collision>
        <geometry>
          <cylinder length="0.0176" radius="0.017"/>
        </geometry>
        <origin rpy="0 0 0" xyz="0 0 0"/>
      </collision>
      <inertial>
        <mass value="0.01" />
        <origin xyz="0 0 0" />
        <inertia ixx="0.001" ixy="0.0" ixz="0.0"
                 iyy="0.001" iyz="0.0"
                 izz="0.001" />
      </inertial>
    </link>

    <joint name="caster_back_joint" type="fixed">
      <parent link="base_link"/>
      <child link="caster_back_link"/>
      <origin xyz="-0.135 0.0 0.009" rpy="${-M_PI/2} 0 0"/>
    </joint>
    <link name="caster_back_link">
      <collision>
        <geometry>
          <cylinder length="0.0176" radius="0.017"/>
        </geometry>
        <origin rpy="0 0 0" xyz="0 0 0"/>
      </collision>
      <inertial>
        <mass value="0.01" />
        <origin xyz="0 0 0" />
        <inertia ixx="0.001" ixy="0.0" ixz="0.0"
                 iyy="0.001" iyz="0.0"
                 izz="0.001" />
      </inertial>
    </link>

    <!-- Kobuki's sensors -->
    <joint name="gyro_joint" type="fixed">
      <axis xyz="0 1 0"/>
      <origin xyz="0.056 0.062 0.0202" rpy="0 0 0"/>
      <parent link="base_link"/>
      <child link="gyro_link"/>
    </joint>
    <link name="gyro_link">
      <inertial>
        <mass value="0.001"/>
        <origin xyz="0 0 0" rpy="0 0 0"/>
        <inertia ixx="0.0001" ixy="0" ixz="0"
                 iyy="0.000001" iyz="0"
                 izz="0.0001"/>
      </inertial>
    </link>

    <joint name="cliff_sensor_left_joint" type="fixed">
      <origin xyz="0.08734 0.13601 0.0214" rpy="0 ${M_PI/2} 0" />
      <parent link="base_link"/>
      <child link="cliff_sensor_left_link" />
    </joint>
    <link name="cliff_sensor_left_link">
      <inertial>
        <mass value="0.0001" />
        <origin xyz="0 0 0" />
        <inertia ixx="0.0001" ixy="0.0" ixz="0.0"
                 iyy="0.0001" iyz="0.0"
                 izz="0.0001" />
      </inertial>
    </link>

    <joint name="cliff_sensor_right_joint" type="fixed">
      <origin xyz="0.085 -0.13601 0.0214" rpy="0 ${M_PI/2} 0" />
      <parent link="base_link"/>
      <child link="cliff_sensor_right_link" />
    </joint>
    <link name="cliff_sensor_right_link">
      <inertial>
        <mass value="0.0001" />
        <origin xyz="0 0 0" />
        <inertia ixx="0.0001" ixy="0.0" ixz="0.0"
                 iyy="0.0001" iyz="0.0"
                 izz="0.0001" />
      </inertial>
    </link>

    <joint name="cliff_sensor_front_joint" type="fixed">
      <origin xyz="0.156 0.00 0.0214" rpy="0 ${M_PI/2} 0" />
      <parent link="base_link"/>
      <child link="cliff_sensor_front_link" />
    </joint>
    <link name="cliff_sensor_front_link">
      <inertial>
        <mass value="0.0001" />
        <origin xyz="0 0 0" />
        <inertia ixx="0.0001" ixy="0.0" ixz="0.0"
                 iyy="0.0001" iyz="0.0"
                 izz="0.0001" />
      </inertial>
    </link>    <!-- uso del lidar -->

    <!--link name="laser">
      <visual>
        <origin xyz="0 0 0.09"/>
        <geometry>
          <box size="0.079 0.05 0.006"/>
        </geometry>
    <material name="support">
      <color rgba="0.5 0.5 0.5 1.0"/>
    </material>
  </visual>
  <visual>
    <origin xyz="0 0 0.12"/>
    <geometry>
      <box size="0.05 0.05 0.07"/>
    </geometry>
    <material name="lidar">
      <color rgba="1.0 0.0 0.0 0.7"/>
    </material>
  </visual>
  <collision>
    <origin xyz="0 0 0.09"/>
    <geometry>
      <box size="0.079 0.05 0.006"/>
    </geometry>
  </collision>
  <collision>
    <origin xyz="0 0 0.131"/>
    <geometry>
      <box size="0.05 0.05 0.07"/>
    </geometry>
  </collision>
</link-->

<!-- depth camera -->

    <!-- camera body, with origin at bottom screw mount -->
    <joint name="camera_joint" type="fixed">
      <origin xyz="-0.07 0.0 0.65" rpy="0 0.610865 0"/>
      <parent link="base_link"/>
      <child link="camera_bottom_screw_frame" />
    </joint>
    <link name="camera_bottom_screw_frame"/>
  
    <joint name="camera_link_joint" type="fixed">
      <origin xyz="0 ${d435_cam_depth_py} ${d435_cam_depth_pz}" rpy="0 0 0"/>
      <parent link="camera_bottom_screw_frame"/>
      <child link="camera_link" />
    </joint>
  
    <link name="camera_link">
      <visual>
      <origin xyz="${d435_cam_mount_from_center_offset} ${-d435_cam_depth_py} 0" rpy="${M_PI/2} 0 ${M_PI/2}"/>
        <geometry>
          <!-- <box size="${d435_cam_width} ${d435_cam_height} ${d435_cam_depth}"/> -->
          <mesh filename="package://jaime_description/meshes/d435.dae" />
          <!--<mesh filename="package://realsense2_description/meshes/d435/d435.dae" />-->
        </geometry>
      </visual>
      <collision>
        <origin xyz="0 ${-d435_cam_depth_py} 0" rpy="0 0 0"/>
        <geometry>
        <box size="${d435_cam_depth} ${d435_cam_width} ${d435_cam_height}"/>
        </geometry>
      </collision>
      <inertial>
        <!-- The following are not reliable values, and should not be used for modeling -->
        <mass value="0.564" />
        <origin xyz="0 0 0" />
        <inertia ixx="0.003881243" ixy="0.0" ixz="0.0" iyy="0.000498940" iyz="0.0" izz="0.003879257" />
      </inertial>
    </link>

 <!-- camera depth joints and links -->
  <joint name="camera_depth_joint" type="fixed">
    <origin xyz="0 0 0" rpy="0 0 0"/>
    <parent link="camera_link"/>
    <child link="camera_depth_frame" />
  </joint>
  <link name="camera_depth_frame"/>

  <joint name="camera_depth_optical_joint" type="fixed">
    <origin xyz="0 0 0" rpy="${-M_PI/2} 0 ${-M_PI/2}" />
    <parent link="camera_depth_frame" />
    <child link="camera_depth_optical_frame" />
  </joint>
  <link name="camera_depth_optical_frame"/>

<!-- camera left IR joints and links -->
<joint name="camera_left_ir_joint" type="fixed">
  <origin xyz="0 ${d435_cam_depth_to_left_ir_offset} 0" rpy="0 0 0" />
  <parent link="camera_depth_frame" />
  <child link="camera_left_ir_frame" />
</joint>
<link name="camera_left_ir_frame"/>

<joint name="camera_left_ir_optical_joint" type="fixed">
  <origin xyz="0 0 0" rpy="${-M_PI/2} 0 ${-M_PI/2}" />
  <parent link="camera_left_ir_frame" />
  <child link="camera_left_ir_optical_frame" />
</joint>
<link name="camera_left_ir_optical_frame"/>

<!-- camera right IR joints and links -->
<joint name="camera_right_ir_joint" type="fixed">
  <origin xyz="0 ${d435_cam_depth_to_right_ir_offset} 0" rpy="0 0 0" />
  <parent link="camera_depth_frame" />
  <child link="camera_right_ir_frame" />
</joint>
<link name="camera_right_ir_frame"/>

<joint name="camera_right_ir_optical_joint" type="fixed">
  <origin xyz="0 0 0" rpy="${-M_PI/2} 0 ${-M_PI/2}" />
  <parent link="camera_right_ir_frame" />
  <child link="camera_right_ir_optical_frame" />
</joint>
<link name="camera_right_ir_optical_frame"/>

<!-- camera color joints and links -->
<joint name="camera_color_joint" type="fixed">
  <origin xyz="0 ${d435_cam_depth_to_color_offset} 0" rpy="0 0 0" />
  <parent link="camera_depth_frame" />
  <child link="camera_color_frame" />
</joint>
<link name="camera_color_frame"/>

<joint name="camera_color_optical_joint" type="fixed">
  <origin xyz="0 0 0" rpy="${-M_PI/2} 0 ${-M_PI/2}" />
  <parent link="camera_color_frame" />
  <child link="camera_color_optical_frame" />
</joint>
<link name="camera_color_optical_frame"/>

<!-- depth camera aligned joints and links-->


<!-- Hokuyo Laser -->
<link name="laser">
  <collision>
    <origin xyz="0 0 0" rpy="0 0 0"/>
    <geometry>
  <box size="0.1 0.1 0.1"/>
    </geometry>
  </collision>

  <visual>
    <origin xyz="0.05 0 -0.05" rpy="0 0 0"/>
    <geometry>
      <mesh filename="package://jaime_description/meshes/hokuyo.dae" />
    </geometry>
  </visual>

  <inertial>
    <mass value="1e-5" />
    <origin xyz="0 0 0" rpy="0 0 0"/>
    <inertia ixx="1e-6" ixy="0" ixz="0" iyy="1e-6" iyz="0" izz="1e-6" />
  </inertial>
</link>

  <joint name="hokuyo_joint" type="fixed">
    <origin xyz="0.0775 0 0.2"/>
    <parent link="cuello_base_link"/>
    <child link="laser"/>
  </joint>

  <link name="laser_frame"/>

  <joint name="laser_joint" type="fixed">
    <origin xyz="0 0 0.064"/>
    <parent link="laser"/>
    <child link="laser_frame"/>
  </joint>




<!--   Cuello   -->




    <link name="cuello_base_link">
        <visual>
          <geometry>
            <mesh filename="package://jaime_description/meshes/meshes_jaime/base_segment.stl" scale="0.001 0.001 0.001"/>
          </geometry>
          <material name="blue"/>
          <origin xyz="0.0 0.0 0" rpy="0.0 0.0 0.0"/>
        </visual>

        <collision>
        <origin xyz="0.0 0.0 0.05" rpy="0.0 0.0 0.0"/>
        <geometry>
          <cylinder radius="0.175" length="0.1"/>
        </geometry>
        </collision>

        <collision>
        <origin xyz="0.0 0.0 0.2" rpy="0.0 0.0 0.0"/>
        <geometry>
          <box size="0.2 0.1 0.2"/>
        </geometry>
        </collision>

        <collision>
        <origin xyz="-0.1 0.0 0.45" rpy="0 -0.3 0.0"/>
        <geometry>
          <box size="0.1 0.1 0.35"/>
        </geometry>
        </collision>

        <collision>
        <origin xyz="-0.15 0.0 0.65" rpy="0 0 0.0"/>
        <geometry>
          <box size="0.15 0.1 0.1"/>
        </geometry>
        </collision>

        <inertial>
          <origin rpy="0 0 0" xyz="-0.048761000000000006 0.0 0.271195"/>
          <mass value="1.6895311238439816"/>
          <inertia ixx="0.08719578772036611" ixy="5.4784475406747093e-17" ixz="0.022449725248199624" iyy="0.09476693416632961" iyz="-2.4061783957761517e-16" izz="0.015163560157224643"/>
        </inertial>
        
      </link>

  <joint name="union_cuello" type="fixed">
    <origin xyz="0.0 0.0 0.1" rpy="0.0 0.0 0.0"/>
    <parent link="base_link"/>
    <child link="cuello_base_link"/>
    <axis xyz="0.0 0.0 0.0"/>

  </joint>



    <link name="entre_cuello_link">
    <origin xyz="0 0.0 -0.02" rpy="0.0 0.0 0.0"/>
      <visual>
        <geometry>
          <mesh filename="package://jaime_description/meshes/meshes_jaime/middle_link.stl" scale="0.001 0.001 0.001"/>
        </geometry>
        <material name="blue"/>
        <origin xyz="0 0.0 -0.02" rpy="0.0 0.0 0.0"/>
      </visual>

      <collision>
      <origin xyz="-0.01 0.0 0.066" rpy="0 -0.2 0.0"/>
      <geometry>
        <box size="0.05 0.1 0.135"/>
      </geometry>
      </collision>

      <inertial>
        <origin rpy="0 0 0" xyz="-0.016311 0.0 0.099931"/>
        <mass value="0.04935881321854115"/>
        <inertia ixx="0.00013683358492508186" ixy="1.0391185824431925e-20" ixz="1.6864941381036664e-05" iyy="0.0001101218997112331" iyz="4.551194773697158e-20" izz="4.4150842757921956e-05"/>
      </inertial>

    </link>

    <link name="cuello_link">
    <origin xyz="0. 0.0 0" rpy="0.0 0.0 0.0"/>
      <visual>
        <geometry>
          <mesh filename="package://jaime_description/meshes/meshes_jaime/middle_segment.stl" scale="0.001 0.001 0.001"/>
        </geometry>
        <material name="white"/>
        <origin xyz="0 0.0 0" rpy="0.0 0.0 0.0"/>
      </visual>

      <collision>
      <origin xyz="-0.0 0.0 0.09" rpy="0 0 0.0"/>
      <geometry>
        <box size="0.12 0.1 0.28"/>
      </geometry>
      </collision>

      <inertial>
        <origin rpy="0 0 0" xyz="-0.008064 0.0 0.08278"/>
        <mass value="0.32942"/>
        <inertia ixx="0.0016762858507607943" ixy="-4.8489364878642617e-20" ixz="-0.00011633194117814697" iyy="0.0018413198294705605" iyz="-1.2568953790911309e-19" izz="0.00030225037441020564"/>
      </inertial>
    </link>

    <link name="entre_cuello_2_link">
    <origin xyz="0.0 0.0 0.0" rpy="0.0 0.0 0.0"/>
      <visual>
        <geometry>
          <mesh filename="package://jaime_description/meshes/meshes_jaime/upper_link.stl" scale="0.001 0.001 0.001"/>
        </geometry>
        <material name="blue"/>
        <origin xyz="0.0 0.0 0" rpy="0.0 0.0 0.0"/>
      </visual>

      <collision>
      <origin xyz="0.03 0.0 0.08" rpy="0 0.3 0.0"/>
      <geometry>
        <box size="0.03 0.05 0.2"/>
      </geometry>
      </collision>

      <inertial>
        <origin rpy="0 0 0" xyz="0.034091 0.0 0.104876"/>
        <mass value="0.019952905767724887"/>
        <inertia ixx="7.401008323582294e-05" ixy="4.2619599656491147e-20" ixz="-2.1641569166888918e-05" iyy="6.762990364652787e-05" iyz="1.346217893341262e-19" izz="2.3087743207129134e-05"/>
      </inertial>

    </link>

    <link name="cuello_2_link">
    <origin xyz="0 0.0 0" rpy="0.0 0.0 0.0"/>
      <visual>
        <geometry>
          <mesh filename="package://jaime_description/meshes/meshes_jaime/upper_segment.stl" scale="0.001 0.001 0.001"/>
        </geometry>
        <material name="white"/>
        <origin xyz="0.0 0.0 0.0" rpy="0.0 0.0 0.0"/>
      </visual>

      <collision>
      <origin xyz="-0.02 0.0 0.03" rpy="0 0.6 0.0"/>
      <geometry>
        <box size="0.08 0.05 0.1"/>
      </geometry>
      </collision>

      <collision>
      <origin xyz="0.03 0.0 0.1" rpy="0 0.6 0.0"/>
      <geometry>
        <box size="0.05 0.05 0.1"/>
      </geometry>
      </collision>

      <inertial>
        <origin rpy="0 0 0" xyz="-0.003079 9.001e-10 0.04753"/>
        <mass value="0.07524443531369857"/>
        <inertia ixx="0.00010323130575479441" ixy="-4.678798365483059e-13" ixz="-5.295549059114918e-05" iyy="0.0001405766236174683" iyz="-2.5520718357180323e-12" izz="5.971848095580196e-05"/>
      </inertial>

    </link>

    <link name="cuello_3_link">
    <origin xyz="0 0.0 0" rpy="0.0 0.0 0.0"/>
      <visual>
        <geometry>
          <mesh filename="package://jaime_description/meshes/meshes_jaime/top_segment.stl" scale="0.001 0.001 0.001"/>
        </geometry>
        <origin xyz="0.0 0.0 0.0" rpy="0.0 0.0 0.0"/>
      </visual>

      <collision>
      <origin xyz="0.05 0.0 0.06" rpy="0 0.785 0.0"/>
      <geometry>
        <box size="0.05 0.05 0.16"/>
      </geometry>
      </collision>

      <inertial>
        <origin rpy="0 0 0" xyz="-0.003079 9.001e-10 0.04753"/>
        <mass value="0.050927614310487625"/>
        <inertia ixx="5.342337042769748e-05" ixy="-1.9238368188254434e-20" ixz="-5.142424748971835e-05" iyy="0.00011356719668945245" iyz="-4.589475851232928e-21" izz="6.775750723831377e-05"/>
      </inertial>

    </link>

    <link name="Tablet">
      <visual>
        <geometry>
          <mesh filename="package://jaime_description/meshes/meshes_jaime/tabletrotada.stl" scale="0.001 0.001 0.001"/>
        </geometry>
        <origin xyz="0.0 0.0 0.0" rpy="0 0 0"/>
      </visual>

      <collision>
      <origin xyz="0.0 0.0 0.0" rpy="0 0 0.0"/>
      <geometry>
        <box size="0.01 0.17 0.25"/>
      </geometry>
      </collision>

      <inertial>
        <origin rpy="0 0 0" xyz="-0.002757 -5.9e-05 -0.002769"/>
        <mass value="1"/>
        <inertia ixx= "0.00485023202551282" ixy="-9.54290973974527e-07" ixz="0.0024813747095519946" iyy="0.0049767308703786315" iyz="9.114384916011426e-07" izz="0.00485023202551282"/>
      </inertial>
    
    </link>



    <joint name="primero" type="revolute">
      <parent link="cuello_base_link"/>
      <child link="entre_cuello_link"/>
      <axis xyz="0 1 0"/>
      <origin xyz="-0.158 0.0 0.68518" rpy="0.0 0 0.0"/>
      <limit upper="0.7" lower="0" velocity="0.0000000000000001" effort="100"/>
      <velocity>0.01</velocity>
    </joint>

    <joint name="segundo" type="revolute">
      <parent link="entre_cuello_link"/>
      <child link="cuello_link"/>
      <axis xyz="0 1 0"/>
      <origin xyz="-0.02 0.0 0.12" rpy="0.0 0 0.0"/>
      <limit upper="0.7" lower="0" velocity="0.0000000000000001" effort="100"/>
      <velocity>0.01</velocity>
    </joint>

    <joint name="tercero" type="revolute">
      <parent link="cuello_link"/>
      <child link="entre_cuello_2_link"/>
      <axis xyz="0 1 0"/>
      <origin xyz="0.03 0.0 0.18" rpy="0.0 0 0.0"/>
      <limit upper="0.7" lower="0" velocity="0.0000000000000001" effort="50"/>
      <velocity>0.01</velocity>
    </joint>

    <joint name="cuarto" type="revolute">
      <parent link="entre_cuello_2_link"/>
      <child link="cuello_2_link"/>
      <axis xyz="0 1 0"/>
      <origin xyz="0.055 0.0 0.16" rpy="0.0 0 0.0"/>
      <limit upper="0.7" lower="0" velocity="0.0000000000000001" effort="50"/>
      <velocity>0.01</velocity>
    </joint>

    <joint name="quinto" type="revolute">
      <parent link="cuello_2_link"/>
      <child link="cuello_3_link"/>
      <axis xyz="0 1 0"/>
      <origin xyz="0.063 0.0 0.138" rpy="0.0 0 0.0"/>
      <limit upper="0.785" lower="0" velocity="0.0000000000000001" effort="50"/>
      <velocity>0.01'</velocity>
    </joint>

    <joint name="tablet" type="fixed">
      <parent link="cuello_3_link"/>
      <child link="Tablet"/>
      <origin xyz="0.13 0.0 0.11" rpy="0.0 0 0.0"/>
    </joint>
<!-- uso del lidar -->

    <!-- Kobuki Gazebo simulation details -->
    <kobuki_sim/>

  </xacro:macro>



  <transmission name="tran1">
    <type>transmission_interface/SimpleTransmission</type>
    <joint name="primero">
      <hardwareInterface>EffortJointInterface</hardwareInterface>
    </joint>
    <actuator name="motor1">
      <hardwareInterface>EffortJointInterface</hardwareInterface>
      <mechanicalReduction>1</mechanicalReduction>
      <velocity>0.00000001</velocity>
    </actuator>
  </transmission>

  

  <transmission name="tran2">
    <type>transmission_interface/SimpleTransmission</type>
    <joint name="segundo">
      <hardwareInterface>EffortJointInterface</hardwareInterface>
    </joint>
    <actuator name="motor2">
      <hardwareInterface>EffortJointInterface</hardwareInterface>
      <mechanicalReduction>1</mechanicalReduction>
      <velocity>0.00000001</velocity>
    </actuator>
  </transmission>
  
  <transmission name="tran3">
    <type>transmission_interface/SimpleTransmission</type>
    <joint name="tercero">
      <hardwareInterface>EffortJointInterface</hardwareInterface>
    </joint>
    <actuator name="motor3">
      <hardwareInterface>EffortJointInterface</hardwareInterface>
      <mechanicalReduction>1</mechanicalReduction>
      <velocity>0.00000001</velocity>
    </actuator>
  </transmission>

  <transmission name="tran4">
    <type>transmission_interface/SimpleTransmission</type>
    <joint name="cuarto">
      <hardwareInterface>EffortJointInterface</hardwareInterface>
    </joint>
    <actuator name="motor4">
      <hardwareInterface>EffortJointInterface</hardwareInterface>
      <mechanicalReduction>1</mechanicalReduction>
      <velocity>0.00000001</velocity>
    </actuator>
  </transmission>

  <transmission name="tran5">
    <type>transmission_interface/SimpleTransmission</type>
    <joint name="quinto">
      <hardwareInterface>EffortJointInterface</hardwareInterface>
    </joint>
    <actuator name="motor5">
      <hardwareInterface>EffortJointInterface</hardwareInterface>
      <mechanicalReduction>1</mechanicalReduction>
      <velocity>0.00000001</velocity>
    </actuator>
  </transmission>


  
</robot>
